
‚ùå normalize_pitcher_and_batter_names ERROR (2025-07-26 12:00:06 PM EDT):
Traceback (most recent call last):
  File "/opt/hostedtoolcache/Python/3.10.18/x64/lib/python3.10/site-packages/pandas/core/indexes/base.py", line 3812, in get_loc
    return self._engine.get_loc(casted_key)
  File "pandas/_libs/index.pyx", line 167, in pandas._libs.index.IndexEngine.get_loc
  File "pandas/_libs/index.pyx", line 196, in pandas._libs.index.IndexEngine.get_loc
  File "pandas/_libs/hashtable_class_helper.pxi", line 7088, in pandas._libs.hashtable.PyObjectHashTable.get_item
  File "pandas/_libs/hashtable_class_helper.pxi", line 7096, in pandas._libs.hashtable.PyObjectHashTable.get_item
KeyError: 'team'

The above exception was the direct cause of the following exception:

Traceback (most recent call last):
  File "/home/runner/work/sports-betting-site/sports-betting-site/scripts/normalize_pitcher_and_batter_names.py", line 50, in <module>
    main()
  File "/home/runner/work/sports-betting-site/sports-betting-site/scripts/normalize_pitcher_and_batter_names.py", line 40, in main
    batters = normalize_dataframe(batters, name_column="last_name, first_name", team_column="team", valid_teams=teams)
  File "/home/runner/work/sports-betting-site/sports-betting-site/scripts/normalize_pitcher_and_batter_names.py", line 31, in normalize_dataframe
    df[team_column] = df[team_column].apply(lambda x: normalize_team(x, valid_teams))
  File "/opt/hostedtoolcache/Python/3.10.18/x64/lib/python3.10/site-packages/pandas/core/frame.py", line 4107, in __getitem__
    indexer = self.columns.get_loc(key)
  File "/opt/hostedtoolcache/Python/3.10.18/x64/lib/python3.10/site-packages/pandas/core/indexes/base.py", line 3819, in get_loc
    raise KeyError(key) from err
KeyError: 'team'

---

