
❌ tag_master_files ERROR (2025-07-26 11:11:47 AM EDT):
INFO: Starting player tagging process...
Traceback (most recent call last):
  File "/opt/hostedtoolcache/Python/3.10.18/x64/lib/python3.10/site-packages/pandas/core/indexes/range.py", line 413, in get_loc
    return self._range.index(new_key)
ValueError: 0 is not in range

The above exception was the direct cause of the following exception:

Traceback (most recent call last):
  File "/home/runner/work/sports-betting-site/sports-betting-site/scripts/tag_master_files.py", line 189, in <module>
    master_players_df["name"] = normalize_name_series(master_players_df["name"])
  File "/home/runner/work/sports-betting-site/sports-betting-site/scripts/tag_master_files.py", line 79, in normalize_name_series
    name_parts_df.loc[~has_comma_mask, 'last'] = space_split[0].str.strip()
  File "/opt/hostedtoolcache/Python/3.10.18/x64/lib/python3.10/site-packages/pandas/core/frame.py", line 4107, in __getitem__
    indexer = self.columns.get_loc(key)
  File "/opt/hostedtoolcache/Python/3.10.18/x64/lib/python3.10/site-packages/pandas/core/indexes/range.py", line 415, in get_loc
    raise KeyError(key) from err
KeyError: 0

---

❌ validate_tagged_players ERROR (2025-07-26 11:11:48 AM EDT):
Traceback (most recent call last):
  File "/home/runner/work/sports-betting-site/sports-betting-site/scripts/validate_tagged_players.py", line 2, in <module>
    from pydantic import BaseModel, ValidationError
ModuleNotFoundError: No module named 'pydantic'

---

