❌ normalize_pitcher_weather_outputs ERROR (2025-08-14 07:26:32 AM EDT):
To https://github.com/Clownworldenjoyer76/baseball_for_mat
 ! [rejected]        main -> main (fetch first)
error: failed to push some refs to 'https://github.com/Clownworldenjoyer76/baseball_for_mat'
hint: Updates were rejected because the remote contains work that you do not
hint: have locally. This is usually caused by another repository pushing to
hint: the same ref. If you want to integrate the remote changes, use
hint: 'git pull' before pushing again.
hint: See the 'Note about fast-forwards' in 'git push --help' for details.
Traceback (most recent call last):
  File "/home/runner/work/baseball_for_mat/baseball_for_mat/scripts/normalize_pitcher_weather_outputs.py", line 53, in <module>
    main()
  File "/home/runner/work/baseball_for_mat/baseball_for_mat/scripts/normalize_pitcher_weather_outputs.py", line 50, in main
    commit_outputs()
  File "/home/runner/work/baseball_for_mat/baseball_for_mat/scripts/normalize_pitcher_weather_outputs.py", line 43, in commit_outputs
    subprocess.run(["git", "push"], check=True)
  File "/opt/hostedtoolcache/Python/3.10.18/x64/lib/python3.10/subprocess.py", line 526, in run
    raise CalledProcessError(retcode, process.args,
subprocess.CalledProcessError: Command '['git', 'push']' returned non-zero exit status 1.

---

