❌ apply_weather_adjustment ERROR (2025-08-30 08:01:33 AM EDT):
Traceback (most recent call last):
  File "/home/runner/work/baseball_for_mat/baseball_for_mat/scripts/apply_weather_adjustment.py", line 117, in <module>
    main()
  File "/home/runner/work/baseball_for_mat/baseball_for_mat/scripts/apply_weather_adjustment.py", line 102, in main
    adj_home = _attach_weather_by_game(bh, wx_by_game)
  File "/home/runner/work/baseball_for_mat/baseball_for_mat/scripts/apply_weather_adjustment.py", line 79, in _attach_weather_by_game
    out = batters.merge(wx_by_game, on=["game_id", "date"], how="left")
  File "/opt/hostedtoolcache/Python/3.10.18/x64/lib/python3.10/site-packages/pandas/core/frame.py", line 10839, in merge
    return merge(
  File "/opt/hostedtoolcache/Python/3.10.18/x64/lib/python3.10/site-packages/pandas/core/reshape/merge.py", line 170, in merge
    op = _MergeOperation(
  File "/opt/hostedtoolcache/Python/3.10.18/x64/lib/python3.10/site-packages/pandas/core/reshape/merge.py", line 807, in __init__
    self._maybe_coerce_merge_keys()
  File "/opt/hostedtoolcache/Python/3.10.18/x64/lib/python3.10/site-packages/pandas/core/reshape/merge.py", line 1509, in _maybe_coerce_merge_keys
    raise ValueError(msg)
ValueError: You are trying to merge on int64 and object columns for key 'game_id'. If you wish to proceed you should use pd.concat

---

❌ apply_park_adjustment ERROR (2025-08-30 08:01:33 AM EDT):
Traceback (most recent call last):
  File "/home/runner/work/baseball_for_mat/baseball_for_mat/scripts/apply_park_adjustment.py", line 111, in <module>
    main()
  File "/home/runner/work/baseball_for_mat/baseball_for_mat/scripts/apply_park_adjustment.py", line 92, in main
    bh2 = _attach_home_team_and_tod(bh, sched, tod)
  File "/home/runner/work/baseball_for_mat/baseball_for_mat/scripts/apply_park_adjustment.py", line 60, in _attach_home_team_and_tod
    x = batters.merge(sched[["game_id", "home_team", "home_key"]], on="game_id", how="left")
  File "/opt/hostedtoolcache/Python/3.10.18/x64/lib/python3.10/site-packages/pandas/core/frame.py", line 10839, in merge
    return merge(
  File "/opt/hostedtoolcache/Python/3.10.18/x64/lib/python3.10/site-packages/pandas/core/reshape/merge.py", line 170, in merge
    op = _MergeOperation(
  File "/opt/hostedtoolcache/Python/3.10.18/x64/lib/python3.10/site-packages/pandas/core/reshape/merge.py", line 807, in __init__
    self._maybe_coerce_merge_keys()
  File "/opt/hostedtoolcache/Python/3.10.18/x64/lib/python3.10/site-packages/pandas/core/reshape/merge.py", line 1509, in _maybe_coerce_merge_keys
    raise ValueError(msg)
ValueError: You are trying to merge on int64 and object columns for key 'game_id'. If you wish to proceed you should use pd.concat

---

