‚ùå fetch_mlb_ids ERROR (2025-08-12 07:38:57 AM EDT):
Traceback (most recent call last):
  File "/home/runner/work/sports-betting-site/sports-betting-site/scripts/fetch_mlb_ids.py", line 146, in <module>
    main()
  File "/home/runner/work/sports-betting-site/sports-betting-site/scripts/fetch_mlb_ids.py", line 126, in main
    merged = df.merge(
  File "/opt/hostedtoolcache/Python/3.10.18/x64/lib/python3.10/site-packages/pandas/core/frame.py", line 10839, in merge
    return merge(
  File "/opt/hostedtoolcache/Python/3.10.18/x64/lib/python3.10/site-packages/pandas/core/reshape/merge.py", line 170, in merge
    op = _MergeOperation(
  File "/opt/hostedtoolcache/Python/3.10.18/x64/lib/python3.10/site-packages/pandas/core/reshape/merge.py", line 794, in __init__
    ) = self._get_merge_keys()
  File "/opt/hostedtoolcache/Python/3.10.18/x64/lib/python3.10/site-packages/pandas/core/reshape/merge.py", line 1298, in _get_merge_keys
    right_keys.append(right._get_label_or_level_values(rk))
  File "/opt/hostedtoolcache/Python/3.10.18/x64/lib/python3.10/site-packages/pandas/core/generic.py", line 1911, in _get_label_or_level_values
    raise KeyError(key)
KeyError: 'home_abbr'

---

