‚ùå apply_weather_adjustment ERROR (2025-08-29 06:16:59 PM EDT):
Traceback (most recent call last):
  File "/home/runner/work/baseball_for_mat/baseball_for_mat/scripts/apply_weather_adjustment.py", line 112, in <module>
    main()
  File "/home/runner/work/baseball_for_mat/baseball_for_mat/scripts/apply_weather_adjustment.py", line 96, in main
    wx_long = _build_weather_by_team()
  File "/home/runner/work/baseball_for_mat/baseball_for_mat/scripts/apply_weather_adjustment.py", line 34, in _build_weather_by_team
    wx_sched = sched.merge(
  File "/opt/hostedtoolcache/Python/3.10.18/x64/lib/python3.10/site-packages/pandas/core/frame.py", line 10839, in merge
    return merge(
  File "/opt/hostedtoolcache/Python/3.10.18/x64/lib/python3.10/site-packages/pandas/core/reshape/merge.py", line 170, in merge
    op = _MergeOperation(
  File "/opt/hostedtoolcache/Python/3.10.18/x64/lib/python3.10/site-packages/pandas/core/reshape/merge.py", line 794, in __init__
    ) = self._get_merge_keys()
  File "/opt/hostedtoolcache/Python/3.10.18/x64/lib/python3.10/site-packages/pandas/core/reshape/merge.py", line 1298, in _get_merge_keys
    right_keys.append(right._get_label_or_level_values(rk))
  File "/opt/hostedtoolcache/Python/3.10.18/x64/lib/python3.10/site-packages/pandas/core/generic.py", line 1911, in _get_label_or_level_values
    raise KeyError(key)
KeyError: 'venue_name'

---

