
‚ùå normalize_pitcher_home_away ERROR (2025-07-27 09:16:01 AM EDT):
2025-07-27 13:16:01,801 - INFO - Starting pitcher data processing and standardization.
2025-07-27 13:16:01,804 - INFO - Loaded team map with 30 entries.
2025-07-27 13:16:01,809 - CRITICAL - An unhandled error occurred during script execution: 'last_name'
Traceback (most recent call last):
  File "/opt/hostedtoolcache/Python/3.10.18/x64/lib/python3.10/site-packages/pandas/core/indexes/base.py", line 3812, in get_loc
    return self._engine.get_loc(casted_key)
  File "pandas/_libs/index.pyx", line 167, in pandas._libs.index.IndexEngine.get_loc
  File "pandas/_libs/index.pyx", line 196, in pandas._libs.index.IndexEngine.get_loc
  File "pandas/_libs/hashtable_class_helper.pxi", line 7088, in pandas._libs.hashtable.PyObjectHashTable.get_item
  File "pandas/_libs/hashtable_class_helper.pxi", line 7096, in pandas._libs.hashtable.PyObjectHashTable.get_item
KeyError: 'last_name'

The above exception was the direct cause of the following exception:

Traceback (most recent call last):
  File "/home/runner/work/sports-betting-site/sports-betting-site/scripts/normalize_pitcher_home_away.py", line 196, in <module>
    process_pitcher_data(pitchers_input, games_input, output_home, output_away)
  File "/home/runner/work/sports-betting-site/sports-betting-site/scripts/normalize_pitcher_home_away.py", line 49, in process_pitcher_data
    pitchers_df["name"] = pitchers_df["last_name"].astype(str).str.strip() + ", " + pitchers_df["first_name"].astype(str).str.strip()
  File "/opt/hostedtoolcache/Python/3.10.18/x64/lib/python3.10/site-packages/pandas/core/frame.py", line 4107, in __getitem__
    indexer = self.columns.get_loc(key)
  File "/opt/hostedtoolcache/Python/3.10.18/x64/lib/python3.10/site-packages/pandas/core/indexes/base.py", line 3819, in get_loc
    raise KeyError(key) from err
KeyError: 'last_name'

---

