2025-07-25 11:11:20,936 - INFO - Starting script: create_pitchers_xtra_updated.py
2025-07-25 11:11:20,936 - INFO - Input file: data/end_chain/cleaned/games_cleaned.csv
2025-07-25 11:11:20,936 - INFO - Reference file: data/cleaned/pitchers_normalized_cleaned.csv
2025-07-25 11:11:20,936 - INFO - Output file: data/end_chain/cleaned/pitchers_xtra_updated.csv
2025-07-25 11:11:20,951 - INFO - Merging team data into output DataFrame...
2025-07-25 11:11:20,953 - CRITICAL - A critical unhandled error occurred: 'team'
Traceback (most recent call last):
  File "/opt/hostedtoolcache/Python/3.10.18/x64/lib/python3.10/site-packages/pandas/core/indexes/base.py", line 3812, in get_loc
    return self._engine.get_loc(casted_key)
  File "pandas/_libs/index.pyx", line 167, in pandas._libs.index.IndexEngine.get_loc
  File "pandas/_libs/index.pyx", line 196, in pandas._libs.index.IndexEngine.get_loc
  File "pandas/_libs/hashtable_class_helper.pxi", line 7088, in pandas._libs.hashtable.PyObjectHashTable.get_item
  File "pandas/_libs/hashtable_class_helper.pxi", line 7096, in pandas._libs.hashtable.PyObjectHashTable.get_item
KeyError: 'team'

The above exception was the direct cause of the following exception:

Traceback (most recent call last):
  File "/home/runner/work/sports-betting-site/sports-betting-site/scripts/create_pitchers_xtra_updated.py", line 174, in <module>
    main()
  File "/home/runner/work/sports-betting-site/sports-betting-site/scripts/create_pitchers_xtra_updated.py", line 153, in main
    missing_teams = output_df["team"].isna().sum()
  File "/opt/hostedtoolcache/Python/3.10.18/x64/lib/python3.10/site-packages/pandas/core/frame.py", line 4107, in __getitem__
    indexer = self.columns.get_loc(key)
  File "/opt/hostedtoolcache/Python/3.10.18/x64/lib/python3.10/site-packages/pandas/core/indexes/base.py", line 3819, in get_loc
    raise KeyError(key) from err
KeyError: 'team'
