Traceback (most recent call last):
  File "/opt/hostedtoolcache/Python/3.10.18/x64/lib/python3.10/site-packages/pandas/core/indexes/base.py", line 3812, in get_loc
    return self._engine.get_loc(casted_key)
  File "pandas/_libs/index.pyx", line 167, in pandas._libs.index.IndexEngine.get_loc
  File "pandas/_libs/index.pyx", line 196, in pandas._libs.index.IndexEngine.get_loc
  File "pandas/_libs/hashtable_class_helper.pxi", line 7088, in pandas._libs.hashtable.PyObjectHashTable.get_item
  File "pandas/_libs/hashtable_class_helper.pxi", line 7096, in pandas._libs.hashtable.PyObjectHashTable.get_item
KeyError: 'away_team'

The above exception was the direct cause of the following exception:

Traceback (most recent call last):
  File "/home/runner/work/sports-betting-site/sports-betting-site/scripts/combine_pitcher_weather_park_away.py", line 52, in <module>
    main()
  File "/home/runner/work/sports-betting-site/sports-betting-site/scripts/combine_pitcher_weather_park_away.py", line 43, in main
    valid_teams = sorted(set(park_df["away_team"].dropna().unique()) | set(weather_df.get("away_team", pd.Series()).dropna().unique()))
  File "/opt/hostedtoolcache/Python/3.10.18/x64/lib/python3.10/site-packages/pandas/core/frame.py", line 4107, in __getitem__
    indexer = self.columns.get_loc(key)
  File "/opt/hostedtoolcache/Python/3.10.18/x64/lib/python3.10/site-packages/pandas/core/indexes/base.py", line 3819, in get_loc
    raise KeyError(key) from err
KeyError: 'away_team'
