‚ùå python ERROR [2025-09-04 02:01:56 PM EDT]:
Traceback (most recent call last):
  File "/home/runner/work/baseball_for_mat/baseball_for_mat/scripts/build_batters_today_from_lineups.py", line 135, in <module>
    main()
  File "/home/runner/work/baseball_for_mat/baseball_for_mat/scripts/build_batters_today_from_lineups.py", line 51, in main
    lu = lu.merge(
  File "/opt/hostedtoolcache/Python/3.10.18/x64/lib/python3.10/site-packages/pandas/core/frame.py", line 10839, in merge
    return merge(
  File "/opt/hostedtoolcache/Python/3.10.18/x64/lib/python3.10/site-packages/pandas/core/reshape/merge.py", line 170, in merge
    op = _MergeOperation(
  File "/opt/hostedtoolcache/Python/3.10.18/x64/lib/python3.10/site-packages/pandas/core/reshape/merge.py", line 813, in __init__
    self._validate_validate_kwd(validate)
  File "/opt/hostedtoolcache/Python/3.10.18/x64/lib/python3.10/site-packages/pandas/core/reshape/merge.py", line 1670, in _validate_validate_kwd
    raise MergeError(
pandas.errors.MergeError: Merge keys are not unique in right dataset; not a many-to-one merge

---

