❌ python ERROR [2025-09-02 08:25:30 PM EDT]:
Traceback (most recent call last):
  File "/home/runner/work/baseball_for_mat/baseball_for_mat/scripts/align_weather_team_keys.py", line 53, in <module>
    main()
  File "/home/runner/work/baseball_for_mat/baseball_for_mat/scripts/align_weather_team_keys.py", line 46, in main
    out = df[["home_team", "away_team"]].copy()
  File "/opt/hostedtoolcache/Python/3.10.18/x64/lib/python3.10/site-packages/pandas/core/frame.py", line 4113, in __getitem__
    indexer = self.columns._get_indexer_strict(key, "columns")[1]
  File "/opt/hostedtoolcache/Python/3.10.18/x64/lib/python3.10/site-packages/pandas/core/indexes/base.py", line 6212, in _get_indexer_strict
    self._raise_if_missing(keyarr, indexer, axis_name)
  File "/opt/hostedtoolcache/Python/3.10.18/x64/lib/python3.10/site-packages/pandas/core/indexes/base.py", line 6261, in _raise_if_missing
    raise KeyError(f"None of [{key}] are in the [{axis_name}]")
KeyError: "None of [Index(['home_team', 'away_team'], dtype='object')] are in the [columns]"

---

❌ python ERROR [2025-09-02 08:25:31 PM EDT]:
Traceback (most recent call last):
  File "/opt/hostedtoolcache/Python/3.10.18/x64/lib/python3.10/site-packages/pandas/core/indexes/base.py", line 3812, in get_loc
    return self._engine.get_loc(casted_key)
  File "pandas/_libs/index.pyx", line 167, in pandas._libs.index.IndexEngine.get_loc
  File "pandas/_libs/index.pyx", line 196, in pandas._libs.index.IndexEngine.get_loc
  File "pandas/_libs/hashtable_class_helper.pxi", line 7088, in pandas._libs.hashtable.PyObjectHashTable.get_item
  File "pandas/_libs/hashtable_class_helper.pxi", line 7096, in pandas._libs.hashtable.PyObjectHashTable.get_item
KeyError: 'avg'

The above exception was the direct cause of the following exception:

Traceback (most recent call last):
  File "/home/runner/work/baseball_for_mat/baseball_for_mat/scripts/project_batter_props.py", line 251, in <module>
    project_batter_props()
  File "/home/runner/work/baseball_for_mat/baseball_for_mat/scripts/project_batter_props.py", line 162, in project_batter_props
    z = _backfill_from_batters(z, bats)
  File "/home/runner/work/baseball_for_mat/baseball_for_mat/scripts/project_batter_props.py", line 145, in _backfill_from_batters
    fill(["proj_avg", "proj_ba", "avg", "ba"], "avg")
  File "/home/runner/work/baseball_for_mat/baseball_for_mat/scripts/project_batter_props.py", line 137, in fill
    z[col_z] = z[col_z].where(z[col_z].notna(), z[col_b])
  File "/opt/hostedtoolcache/Python/3.10.18/x64/lib/python3.10/site-packages/pandas/core/frame.py", line 4107, in __getitem__
    indexer = self.columns.get_loc(key)
  File "/opt/hostedtoolcache/Python/3.10.18/x64/lib/python3.10/site-packages/pandas/core/indexes/base.py", line 3819, in get_loc
    raise KeyError(key) from err
KeyError: 'avg'

---

