‚ùå project_prep.py ERROR [2025-09-05 09:12:44 AM EDT]:
Traceback (most recent call last):
  File "/home/runner/work/baseball_for_mat/baseball_for_mat/scripts/project_prep.py", line 80, in <module>
    project_prep()
  File "/home/runner/work/baseball_for_mat/baseball_for_mat/scripts/project_prep.py", line 53, in project_prep
    df_startingpitchers = df_startingpitchers.merge(
  File "/opt/hostedtoolcache/Python/3.10.18/x64/lib/python3.10/site-packages/pandas/core/frame.py", line 10839, in merge
    return merge(
  File "/opt/hostedtoolcache/Python/3.10.18/x64/lib/python3.10/site-packages/pandas/core/reshape/merge.py", line 170, in merge
    op = _MergeOperation(
  File "/opt/hostedtoolcache/Python/3.10.18/x64/lib/python3.10/site-packages/pandas/core/reshape/merge.py", line 794, in __init__
    ) = self._get_merge_keys()
  File "/opt/hostedtoolcache/Python/3.10.18/x64/lib/python3.10/site-packages/pandas/core/reshape/merge.py", line 1311, in _get_merge_keys
    left_keys.append(left._get_label_or_level_values(lk))
  File "/opt/hostedtoolcache/Python/3.10.18/x64/lib/python3.10/site-packages/pandas/core/generic.py", line 1911, in _get_label_or_level_values
    raise KeyError(key)
KeyError: 'last_name, first_name'

---

