‚ùå project_prep.py ERROR [2025-09-05 10:00:38 AM EDT]:
Traceback (most recent call last):
  File "/opt/hostedtoolcache/Python/3.10.18/x64/lib/python3.10/site-packages/pandas/core/indexes/base.py", line 3812, in get_loc
    return self._engine.get_loc(casted_key)
  File "pandas/_libs/index.pyx", line 167, in pandas._libs.index.IndexEngine.get_loc
  File "pandas/_libs/index.pyx", line 196, in pandas._libs.index.IndexEngine.get_loc
  File "pandas/_libs/hashtable_class_helper.pxi", line 7088, in pandas._libs.hashtable.PyObjectHashTable.get_item
  File "pandas/_libs/hashtable_class_helper.pxi", line 7096, in pandas._libs.hashtable.PyObjectHashTable.get_item
KeyError: 'game_id'

The above exception was the direct cause of the following exception:

Traceback (most recent call last):
  File "/home/runner/work/baseball_for_mat/baseball_for_mat/scripts/project_prep.py", line 89, in <module>
    project_prep()
  File "/home/runner/work/baseball_for_mat/baseball_for_mat/scripts/project_prep.py", line 67, in project_prep
    df_startingpitchers["game_id"] = df_startingpitchers["game_id"].fillna("UNKNOWN")
  File "/opt/hostedtoolcache/Python/3.10.18/x64/lib/python3.10/site-packages/pandas/core/frame.py", line 4107, in __getitem__
    indexer = self.columns.get_loc(key)
  File "/opt/hostedtoolcache/Python/3.10.18/x64/lib/python3.10/site-packages/pandas/core/indexes/base.py", line 3819, in get_loc
    raise KeyError(key) from err
KeyError: 'game_id'

---

