‚ùå clean_inject_team_ids.py ERROR [2025-09-06 01:26:11 AM EDT]:
Traceback (most recent call last):
  File "/opt/hostedtoolcache/Python/3.10.18/x64/lib/python3.10/site-packages/pandas/core/indexes/base.py", line 3812, in get_loc
    return self._engine.get_loc(casted_key)
  File "pandas/_libs/index.pyx", line 167, in pandas._libs.index.IndexEngine.get_loc
  File "pandas/_libs/index.pyx", line 196, in pandas._libs.index.IndexEngine.get_loc
  File "pandas/_libs/hashtable_class_helper.pxi", line 7088, in pandas._libs.hashtable.PyObjectHashTable.get_item
  File "pandas/_libs/hashtable_class_helper.pxi", line 7096, in pandas._libs.hashtable.PyObjectHashTable.get_item
KeyError: 'team_id_dir'

The above exception was the direct cause of the following exception:

Traceback (most recent call last):
  File "/home/runner/work/baseball_for_mat/baseball_for_mat/scripts/clean_inject_team_ids.py", line 102, in <module>
    main()
  File "/home/runner/work/baseball_for_mat/baseball_for_mat/scripts/clean_inject_team_ids.py", line 93, in main
    merge_team_id(BATTERS_PROJECTED_FILE, team_dir, mode="create")
  File "/home/runner/work/baseball_for_mat/baseball_for_mat/scripts/clean_inject_team_ids.py", line 68, in merge_team_id
    merged["team_id"] = merged["team_id_dir"]
  File "/opt/hostedtoolcache/Python/3.10.18/x64/lib/python3.10/site-packages/pandas/core/frame.py", line 4107, in __getitem__
    indexer = self.columns.get_loc(key)
  File "/opt/hostedtoolcache/Python/3.10.18/x64/lib/python3.10/site-packages/pandas/core/indexes/base.py", line 3819, in get_loc
    raise KeyError(key) from err
KeyError: 'team_id_dir'

---

